Workbook

Sheet BDD_PRODUITS
A1: PRODUIT.ID | B1: DB.LIB | C1: COMPTE.LIB | D1: QTE.2022 | E1: QTE.2023 | F1: QTE.2024 | G1: QTE.Total
A2: 601540 | B2: RAI DEPISTAGE (B50) REF RAID2 | C2: EFS EXAMENS GREFFES HLA ETMALADIES | D2: 35 | E2: 35 | G2: =SUM(BDD_PRODUITS!$D2:$F2) -> 70
A3: 601615 | B3: SUPPLEMENT DIMANCHE (B20) REF 9004 | C3: EFS EXAMENS GREFFES HLA ETMALADIES | E3: 78 | G3: =SUM(BDD_PRODUITS!$D3:$F3) -> 78
A4: 246363 | B4: RAI DEPISTAGE TIA | C4: EFS EXAMENS GREFFES HLA ETMALADIES | E4: 245 | G4: =SUM(BDD_PRODUITS!$D4:$F4) -> 245
A5: 601541 | B5: PHENOTYPE RHESUS KELL (B40) REF RHK | C5: EFS EXAMENS GREFFES HLA ETMALADIES | D5: 66 | E5: 330 | G5: =SUM(BDD_PRODUITS!$D5:$F5) -> 396
A6: 601583 | B6: GROUPE SANGUIN ABO RH(D) (B35) REF ABOD | C6: EFS EXAMENS GREFFES HLA ETMALADIES | D6: 66 | E6: 330 | G6: =SUM(BDD_PRODUITS!$D6:$F6) -> 396
A7: 61651 | B7: DEVIS N°Q2387840 - PHANTOM-TOS | C7: ACCESSOIRES MATERIEL MEDICAL | F7: 1 | G7: =SUM(BDD_PRODUITS!$D7:$F7) -> 1
A8: 61651 | B8: MANDRIN DE JACOB DIAM. 6,35 MM DRILL | C8: ACCESSOIRES MATERIEL MEDICAL | F8: 1 | G8: =SUM(BDD_PRODUITS!$D8:$F8) -> 1
A9: 61651 | B9: Modèle de palpation mammaire + valise de transport | C9: ACCESSOIRES MATERIEL MEDICAL | F9: 1 | G9: =SUM(BDD_PRODUITS!$D9:$F9) -> 1
A10: 61651 | B10: PASSE BROCHES 0,7 A 1.8 MM | C10: ACCESSOIRES MATERIEL MEDICAL | F10: 1 | G10: =SUM(BDD_PRODUITS!$D10:$F10) -> 1
A11: 61651 | B11: POWER SUPPLY 24V | C11: ACCESSOIRES MATERIEL MEDICAL | F11: 1 | G11: =SUM(BDD_PRODUITS!$D11:$F11) -> 1
A12: 61651 | B12: RETINOMAX PRINTER 5 | C12: ACCESSOIRES MATERIEL MEDICAL | F12: 1 | G12: =SUM(BDD_PRODUITS!$D12:$F12) -> 1
A13: 61651 | B13: Tablette IPAD configurée avec l'application logicielle EZYGAIN compatible tapis ema® et réalité | C13: ACCESSOIRES MATERIEL MEDICAL | F13: 1 | G13: =SUM(BDD_PRODUITS!$D13:$F13) -> 1
A14: 222865 | B14: CADRE DE MARCHE DAYS FIXE STANDARD (UNITE) REF 1809460 - SUBSTITUTION OK : REF CO | C14: ACCESSOIRES MATERIEL MEDICAL | D14: 1 | G14: =SUM(BDD_PRODUITS!$D14:$F14) -> 1
A15: 222865 | B15: CADRE DE MARCHE DAYS FIXE STANDARD(UNI TE)REF CONSTR : 091356591 | C15: ACCESSOIRES MATERIEL MEDICAL | E15: 1 | G15: =SUM(BDD_PRODUITS!$D15:$F15) -> 1
A16: 222865 | B16: CADRE DE MARCHE DAYS FIXE - OMEGA (UNITE) Ref Constr : 21010000 SCEMED | C16: ACCESSOIRES MATERIEL MEDICAL | F16: 1 | G16: =SUM(BDD_PRODUITS!$D16:$F16) -> 1
A17: 213594 | B17: MATELAS A EAU 4.5L + ANTI-ALGUE POURBA BYWARMER BW3-020 (UNITE)#24 | C17: ACCESSOIRES MATERIEL MEDICAL | F17: 1 | G17: =SUM(BDD_PRODUITS!$D17:$F17) -> 1
A18: 218420 | B18: DRAP DE TRANSFERT MULTIGLIDE 130X80CM (UNITE) | C18: ACCESSOIRES MATERIEL MEDICAL | D18: 1 | G18: =SUM(BDD_PRODUITS!$D18:$F18) -> 1
A19: 224913 | B19: TENSIOMETRE DE VAQUEZ NANO NOIR ADULTE TAILLE M (UNITE) | C19: ACCESSOIRES MATERIEL MEDICAL | F19: 1 | G19: =SUM(BDD_PRODUITS!$D19:$F19) -> 1
A20: 244061 | B20: TOISE MURALE ADULTE 2M AVEC CURSEUR NYLON ##21 | C20: ACCESSOIRES MATERIEL MEDICAL | E20: 1 | G20: =SUM(BDD_PRODUITS!$D20:$F20) -> 1
A21: 244061 | B21: TOISE MURALE ADULTE 2M AVEC CURSEURNYL ON##23 | C21: ACCESSOIRES MATERIEL MEDICAL | E21: 1 | G21: =SUM(BDD_PRODUITS!$D21:$F21) -> 1
A22: 211100 | B22: COUSSIN UNIVERSEL STANDARD XL 40*60CM REF NEG0381 #24 | C22: ACCESSOIRES MATERIEL MEDICAL | F22: 1 | G22: =SUM(BDD_PRODUITS!$D22:$F22) -> 1
A23: 218181 | B23: BARRE CANOLI DE REDRESSEMENT POUR LITM EDICALISE (DEBARCOUL90)(UNITE) ref 3325735 | C23: ACCESSOIRES MATERIEL MEDICAL | F23: 1 | G23: =SUM(BDD_PRODUITS!$D23:$F23) -> 1
A24: 200013 | B24: DEAMBULATEUR 3 ROUES DRIVE MADRID PANIER & SAC (UNITE) | C24: ACCESSOIRES MATERIEL MEDICAL | F24: 1 | G24: =SUM(BDD_PRODUITS!$D24:$F24) -> 1
A25: 200013 | B25: DEAMBULATEUR 3 ROUES (UNITE) | C25: ACCESSOIRES MATERIEL MEDICAL | E25: 1 | G25: =SUM(BDD_PRODUITS!$D25:$F25) -> 1
A26: 200013 | B26: DEAMBULATEUR 3 ROUES DRIVE MADRID PANIER & SAC (UNITE) | C26: ACCESSOIRES MATERIEL MEDICAL | F26: 1 | G26: =SUM(BDD_PRODUITS!$D26:$F26) -> 1
A27: 211111 | B27: ROLLATOR 2 ROUES BLEU (UNITE) | C27: ACCESSOIRES MATERIEL MEDICAL | E27: 1 | G27: =SUM(BDD_PRODUITS!$D27:$F27) -> 1
A28: 211111 | B28: ROLLATOR 2 ROUES BLEU (UNITE) REF CONSTR 91558006 | C28: ACCESSOIRES MATERIEL MEDICAL | D28: 1 | G28: =SUM(BDD_PRODUITS!$D28:$F28) -> 1
A29: 213472 | B29: DIAPASON HARTMANN SANS CURSEUR 512VD (UNITE)#23 REF DIA512 | C29: ACCESSOIRES MATERIEL MEDICAL | E29: 1 | G29: =SUM(BDD_PRODUITS!$D29:$F29) -> 1
A30: 213472 | B30: DIAPASON HARTMANN SANS CURSEUR 512VD(U NITE)REF DIA512 | C30: ACCESSOIRES MATERIEL MEDICAL | D30: 1 | G30: =SUM(BDD_PRODUITS!$D30:$F30) -> 1
A31: 213483 | B31: PELVIC-TILT REGLABLE (10 UNITES) #24 | C31: ACCESSOIRES MATERIEL MEDICAL | F31: 1 | G31: =SUM(BDD_PRODUITS!$D31:$F31) -> 1
A32: 218459 | B32: FEMUR GAUCHE (UNITE) REF 1019360 | C32: ACCESSOIRES MATERIEL MEDICAL | E32: 1 | G32: =SUM(BDD_PRODUITS!$D32:$F32) -> 1
A33: 218778 | B33: LUNETTES PRISMATIQUES VE223 (PAIRE)REF VE223 | C33: ACCESSOIRES MATERIEL MEDICAL | E33: 1 | G33: =SUM(BDD_PRODUITS!$D33:$F33) -> 1
A34: 231532 | B34: PÈSE PERSONNE SECA_878_DR (UNITE) REF CONSTR 8787041119 REF FOURN 3299906 | C34: ACCESSOIRES MATERIEL MEDICAL | E34: 1 | G34: =SUM(BDD_PRODUITS!$D34:$F34) -> 1
A35: 244870 | B35: SET DE CONNEXION EN SILICONE, POUR COLOSCOPES, GASTROSCOPES ET | C35: ACCESSOIRES MATERIEL MEDICAL | E35: 1 | G35: =SUM(BDD_PRODUITS!$D35:$F35) -> 1
A36: 244870 | B36: SET DE CONNEXION EN SILICONE, POURCOLO SCOPES, GASTROSCOPES ETDUODENESCOPES S | C36: ACCESSOIRES MATERIEL MEDICAL | E36: 1 | G36: =SUM(BDD_PRODUITS!$D36:$F36) -> 1
A37: 245669 | B37: HUGO-ADAPTATEUR ENDOSCOPE(UNITE) | C37: ACCESSOIRES MATERIEL MEDICAL | E37: 1 | G37: =SUM(BDD_PRODUITS!$D37:$F37) -> 1
A38: 213599 | B38: PLANCHE DE TRANSFERT BANANA 68*21CM(UN ITE)#23REF SIECA622000 | C38: ACCESSOIRES MATERIEL MEDICAL | E38: 1 | G38: =SUM(BDD_PRODUITS!$D38:$F38) -> 1
A39: 215211 | B39: MONITEUR O2 ENVITEC MY SIGN O (UNITE) | C39: ACCESSOIRES MATERIEL MEDICAL | F39: 1 | G39: =SUM(BDD_PRODUITS!$D39:$F39) -> 1
A40: 218175 | B40: TROUSSE DE SECOURS MULTISAN 12-25PERSO NNES VIDE (UNITE)REF MULTISANV | C40: ACCESSOIRES MATERIEL MEDICAL | F40: 1 | G40: =SUM(BDD_PRODUITS!$D40:$F40) -> 1
...

Sheet dictionnaire
A1: PRODUIT.ID | B1: identifiant du produit
A2: DB.LIB | B2: Libellé du produit, quantité et unité
A3: COMPTE.LIB | B3: libellé du compte associé
A4: QTE.2022 | B4: Quantité 2022
A5: QTE.2023 | B5: Quantité 2023
A6: QTE.2024 | B6: Quantité 2024
A7: QTE.total | B7: Quantité total entre 2022 et 2024
